2024-02-23 10:17:02,308 ERROR: Exception on /ver_notas_pedido [GET] [in /var/www/html/SistemaVentasFlask/env/lib/python3.11/site-packages/flask/app.py:828]
Traceback (most recent call last):
  File "/var/www/html/SistemaVentasFlask/env/lib/python3.11/site-packages/sqlalchemy/engine/base.py", line 1960, in _exec_single_context
    self.dialect.do_execute(
  File "/var/www/html/SistemaVentasFlask/env/lib/python3.11/site-packages/sqlalchemy/engine/default.py", line 924, in do_execute
    cursor.execute(statement, parameters)
  File "/var/www/html/SistemaVentasFlask/env/lib/python3.11/site-packages/pymysql/cursors.py", line 153, in execute
    result = self._query(query)
             ^^^^^^^^^^^^^^^^^^
  File "/var/www/html/SistemaVentasFlask/env/lib/python3.11/site-packages/pymysql/cursors.py", line 322, in _query
    conn.query(q)
  File "/var/www/html/SistemaVentasFlask/env/lib/python3.11/site-packages/pymysql/connections.py", line 558, in query
    self._affected_rows = self._read_query_result(unbuffered=unbuffered)
                          ^^^^^^^^^^^^^^^^^^^^^^^^^^^^^^^^^^^^^^^^^^^^^^
  File "/var/www/html/SistemaVentasFlask/env/lib/python3.11/site-packages/pymysql/connections.py", line 822, in _read_query_result
    result.read()
  File "/var/www/html/SistemaVentasFlask/env/lib/python3.11/site-packages/pymysql/connections.py", line 1200, in read
    first_packet = self.connection._read_packet()
                   ^^^^^^^^^^^^^^^^^^^^^^^^^^^^^^
  File "/var/www/html/SistemaVentasFlask/env/lib/python3.11/site-packages/pymysql/connections.py", line 772, in _read_packet
    packet.raise_for_error()
  File "/var/www/html/SistemaVentasFlask/env/lib/python3.11/site-packages/pymysql/protocol.py", line 221, in raise_for_error
    err.raise_mysql_exception(self._data)
  File "/var/www/html/SistemaVentasFlask/env/lib/python3.11/site-packages/pymysql/err.py", line 143, in raise_mysql_exception
    raise errorclass(errno, errval)
pymysql.err.OperationalError: (1054, "Unknown column 'notapedido.usuario_id' in 'field list'")

The above exception was the direct cause of the following exception:

Traceback (most recent call last):
  File "/var/www/html/SistemaVentasFlask/env/lib/python3.11/site-packages/flask/app.py", line 1463, in wsgi_app
    response = self.full_dispatch_request()
               ^^^^^^^^^^^^^^^^^^^^^^^^^^^^
  File "/var/www/html/SistemaVentasFlask/env/lib/python3.11/site-packages/flask/app.py", line 872, in full_dispatch_request
    rv = self.handle_user_exception(e)
         ^^^^^^^^^^^^^^^^^^^^^^^^^^^^^
  File "/var/www/html/SistemaVentasFlask/env/lib/python3.11/site-packages/flask/app.py", line 870, in full_dispatch_request
    rv = self.dispatch_request()
         ^^^^^^^^^^^^^^^^^^^^^^^
  File "/var/www/html/SistemaVentasFlask/env/lib/python3.11/site-packages/flask/app.py", line 855, in dispatch_request
    return self.ensure_sync(self.view_functions[rule.endpoint])(**view_args)  # type: ignore[no-any-return]
           ^^^^^^^^^^^^^^^^^^^^^^^^^^^^^^^^^^^^^^^^^^^^^^^^^^^^^^^^^^^^^^^^^
  File "/var/www/html/SistemaVentasFlask/env/lib/python3.11/site-packages/flask_login/utils.py", line 290, in decorated_view
    return current_app.ensure_sync(func)(*args, **kwargs)
           ^^^^^^^^^^^^^^^^^^^^^^^^^^^^^^^^^^^^^^^^^^^^^^
  File "/var/www/html/SistemaVentasFlask/app/routes/note.py", line 422, in ver_notas_pedido
    notas_pedidos_actual=Nota_de_Pedido.query.filter(Nota_de_Pedido.nombre_comprador.like('%'+comprador+'%')).order_by(asc(Nota_de_Pedido.id)).all()
                         ^^^^^^^^^^^^^^^^^^^^^^^^^^^^^^^^^^^^^^^^^^^^^^^^^^^^^^^^^^^^^^^^^^^^^^^^^^^^^^^^^^^^^^^^^^^^^^^^^^^^^^^^^^^^^^^^^^^^^^^^^^^
  File "/var/www/html/SistemaVentasFlask/env/lib/python3.11/site-packages/sqlalchemy/orm/query.py", line 2672, in all
    return self._iter().all()  # type: ignore
           ^^^^^^^^^^^^
  File "/var/www/html/SistemaVentasFlask/env/lib/python3.11/site-packages/sqlalchemy/orm/query.py", line 2826, in _iter
    result: Union[ScalarResult[_T], Result[_T]] = self.session.execute(
                                                  ^^^^^^^^^^^^^^^^^^^^^
  File "/var/www/html/SistemaVentasFlask/env/lib/python3.11/site-packages/sqlalchemy/orm/session.py", line 2306, in execute
    return self._execute_internal(
           ^^^^^^^^^^^^^^^^^^^^^^^
  File "/var/www/html/SistemaVentasFlask/env/lib/python3.11/site-packages/sqlalchemy/orm/session.py", line 2191, in _execute_internal
    result: Result[Any] = compile_state_cls.orm_execute_statement(
                          ^^^^^^^^^^^^^^^^^^^^^^^^^^^^^^^^^^^^^^^^
  File "/var/www/html/SistemaVentasFlask/env/lib/python3.11/site-packages/sqlalchemy/orm/context.py", line 293, in orm_execute_statement
    result = conn.execute(
             ^^^^^^^^^^^^^
  File "/var/www/html/SistemaVentasFlask/env/lib/python3.11/site-packages/sqlalchemy/engine/base.py", line 1408, in execute
    return meth(
           ^^^^^
  File "/var/www/html/SistemaVentasFlask/env/lib/python3.11/site-packages/sqlalchemy/sql/elements.py", line 513, in _execute_on_connection
    return connection._execute_clauseelement(
           ^^^^^^^^^^^^^^^^^^^^^^^^^^^^^^^^^^
  File "/var/www/html/SistemaVentasFlask/env/lib/python3.11/site-packages/sqlalchemy/engine/base.py", line 1630, in _execute_clauseelement
    ret = self._execute_context(
          ^^^^^^^^^^^^^^^^^^^^^^
  File "/var/www/html/SistemaVentasFlask/env/lib/python3.11/site-packages/sqlalchemy/engine/base.py", line 1839, in _execute_context
    return self._exec_single_context(
           ^^^^^^^^^^^^^^^^^^^^^^^^^^
  File "/var/www/html/SistemaVentasFlask/env/lib/python3.11/site-packages/sqlalchemy/engine/base.py", line 1979, in _exec_single_context
    self._handle_dbapi_exception(
  File "/var/www/html/SistemaVentasFlask/env/lib/python3.11/site-packages/sqlalchemy/engine/base.py", line 2335, in _handle_dbapi_exception
    raise sqlalchemy_exception.with_traceback(exc_info[2]) from e
  File "/var/www/html/SistemaVentasFlask/env/lib/python3.11/site-packages/sqlalchemy/engine/base.py", line 1960, in _exec_single_context
    self.dialect.do_execute(
  File "/var/www/html/SistemaVentasFlask/env/lib/python3.11/site-packages/sqlalchemy/engine/default.py", line 924, in do_execute
    cursor.execute(statement, parameters)
  File "/var/www/html/SistemaVentasFlask/env/lib/python3.11/site-packages/pymysql/cursors.py", line 153, in execute
    result = self._query(query)
             ^^^^^^^^^^^^^^^^^^
  File "/var/www/html/SistemaVentasFlask/env/lib/python3.11/site-packages/pymysql/cursors.py", line 322, in _query
    conn.query(q)
  File "/var/www/html/SistemaVentasFlask/env/lib/python3.11/site-packages/pymysql/connections.py", line 558, in query
    self._affected_rows = self._read_query_result(unbuffered=unbuffered)
                          ^^^^^^^^^^^^^^^^^^^^^^^^^^^^^^^^^^^^^^^^^^^^^^
  File "/var/www/html/SistemaVentasFlask/env/lib/python3.11/site-packages/pymysql/connections.py", line 822, in _read_query_result
    result.read()
  File "/var/www/html/SistemaVentasFlask/env/lib/python3.11/site-packages/pymysql/connections.py", line 1200, in read
    first_packet = self.connection._read_packet()
                   ^^^^^^^^^^^^^^^^^^^^^^^^^^^^^^
  File "/var/www/html/SistemaVentasFlask/env/lib/python3.11/site-packages/pymysql/connections.py", line 772, in _read_packet
    packet.raise_for_error()
  File "/var/www/html/SistemaVentasFlask/env/lib/python3.11/site-packages/pymysql/protocol.py", line 221, in raise_for_error
    err.raise_mysql_exception(self._data)
  File "/var/www/html/SistemaVentasFlask/env/lib/python3.11/site-packages/pymysql/err.py", line 143, in raise_mysql_exception
    raise errorclass(errno, errval)
sqlalchemy.exc.OperationalError: (pymysql.err.OperationalError) (1054, "Unknown column 'notapedido.usuario_id' in 'field list'")
[SQL: SELECT notapedido.id AS notapedido_id, notapedido.fecha_creacion AS notapedido_fecha_creacion, notapedido.nombre_comprador AS notapedido_nombre_comprador, notapedido.nombre_producto AS notapedido_nombre_producto, notapedido.total_venta AS notapedido_total_venta, notapedido.bool_acuenta AS notapedido_bool_acuenta, notapedido.acuenta AS notapedido_acuenta, notapedido.deuda AS notapedido_deuda, notapedido.bool_deuda AS notapedido_bool_deuda, notapedido.direccion_comprador AS notapedido_direccion_comprador, notapedido.estado AS notapedido_estado, notapedido.fecha_cancelacion AS notapedido_fecha_cancelacion, notapedido.comentario AS notapedido_comentario, notapedido.numero_comprador AS notapedido_numero_comprador, notapedido.dni_comprador AS notapedido_dni_comprador, notapedido.vuelto AS notapedido_vuelto, notapedido.`pagoEfectivo` AS `notapedido_pagoEfectivo`, notapedido.`pagoVisa` AS `notapedido_pagoVisa`, notapedido.`pagoBBVA` AS `notapedido_pagoBBVA`, notapedido.`pagoBCP` AS `notapedido_pagoBCP`, notapedido.`pagoYape` AS `notapedido_pagoYape`, notapedido.usuario_id AS notapedido_usuario_id, notapedido.comprador_id AS notapedido_comprador_id 
FROM notapedido 
WHERE notapedido.nombre_comprador LIKE %(nombre_comprador_1)s ORDER BY notapedido.id ASC]
[parameters: {'nombre_comprador_1': '%elvi%'}]
(Background on this error at: https://sqlalche.me/e/20/e3q8)
